<?xml version="1.0" ?>
<!-- =================================================================================== -->
<!-- |    This document was autogenerated by xacro from open_manipulator_description.urdf.xacro | -->
<!-- |    EDITING THIS FILE BY HAND IS NOT RECOMMENDED                                 | -->
<!-- =================================================================================== -->
<!-- Open_Manipulator Chain -->
<robot name="open_manipulator" xmlns:xacro="http://www.ros.org/wiki/xacro">
  <!-- World -->
  <gazebo reference="world">
  </gazebo>
  <!-- Base Link -->
  <gazebo reference="base_link">
    <kp>1000000.0</kp>
    <kd>100.0</kd>
    <mu1>30.0</mu1>
    <mu2>30.0</mu2>
    <maxVel>1.0</maxVel>
    <minDepth>0.001</minDepth>
    <material>Gazebo/DarkGrey</material>
  </gazebo>
  <!-- Link1 -->
  <gazebo reference="link1">
    <kp>1000000.0</kp>
    <kd>100.0</kd>
    <mu1>30.0</mu1>
    <mu2>30.0</mu2>
    <maxVel>1.0</maxVel>
    <minDepth>0.001</minDepth>
    <material>Gazebo/DarkGrey</material>
  </gazebo>
  <!-- Link2 -->
  <gazebo reference="link2">
    <kp>1000000.0</kp>
    <kd>100.0</kd>
    <mu1>30.0</mu1>
    <mu2>30.0</mu2>
    <maxVel>1.0</maxVel>
    <minDepth>0.001</minDepth>
    <material>Gazebo/DarkGrey</material>
  </gazebo>
  <!-- Link3 -->
  <gazebo reference="link3">
    <kp>1000000.0</kp>
    <kd>100.0</kd>
    <mu1>30.0</mu1>
    <mu2>30.0</mu2>
    <maxVel>1.0</maxVel>
    <minDepth>0.001</minDepth>
    <material>Gazebo/DarkGrey</material>
  </gazebo>
  <!-- Link4 -->
  <gazebo reference="link4">
    <kp>1000000.0</kp>
    <kd>100.0</kd>
    <mu1>30.0</mu1>
    <mu2>30.0</mu2>
    <maxVel>1.0</maxVel>
    <minDepth>0.001</minDepth>
    <material>Gazebo/DarkGrey</material>
  </gazebo>
  <!-- Link5 -->
  <gazebo reference="link5">
    <kp>1000000.0</kp>
    <kd>100.0</kd>
    <mu1>30.0</mu1>
    <mu2>30.0</mu2>
    <maxVel>1.0</maxVel>
    <minDepth>0.001</minDepth>
    <material>Gazebo/DarkGrey</material>
  </gazebo>
  <!-- Link6 -->
  <gazebo reference="link6">
    <kp>1000000.0</kp>
    <kd>100.0</kd>
    <mu1>30.0</mu1>
    <mu2>30.0</mu2>
    <maxVel>1.0</maxVel>
    <minDepth>0.001</minDepth>
    <material>Gazebo/DarkGrey</material>
  </gazebo>
  <!-- Link7 -->
  <gazebo reference="link7">
    <kp>1000000.0</kp>
    <kd>100.0</kd>
    <mu1>30.0</mu1>
    <mu2>30.0</mu2>
    <maxVel>1.0</maxVel>
    <minDepth>0.001</minDepth>
    <material>Gazebo/DarkGrey</material>
  </gazebo>
  <!-- grip_link -->
  <gazebo reference="grip_link">
    <kp>1000000.0</kp>
    <kd>100.0</kd>
    <mu1>30.0</mu1>
    <mu2>30.0</mu2>
    <maxVel>1.0</maxVel>
    <minDepth>0.001</minDepth>
    <material>Gazebo/DarkGrey</material>
  </gazebo>
  <!-- ros_control plugin -->
  <gazebo>
    <plugin filename="libgazebo_ros_control.so" name="gazebo_ros_control">
      <robotNamespace>/open_manipulator</robotNamespace>
      <controlPeriod>0.001</controlPeriod>
      <robotSimType>gazebo_ros_control/DefaultRobotHWSim</robotSimType>
    </plugin>
  </gazebo>
  <material name="black">
    <color rgba="0.0 0.0 0.0 1.0"/>
  </material>
  <material name="white">
    <color rgba="1.0 1.0 1.0 1.0"/>
  </material>
  <material name="red">
    <color rgba="0.8 0.0 0.0 1.0"/>
  </material>
  <material name="blue">
    <color rgba="0.0 0.0 0.8 1.0"/>
  </material>
  <material name="green">
    <color rgba="0.0 0.8 0.0 1.0"/>
  </material>
  <material name="grey">
    <color rgba="0.5 0.5 0.5 1.0"/>
  </material>
  <material name="orange">
    <color rgba="1.0 0.423529411765 0.0392156862745 1.0"/>
  </material>
  <material name="brown">
    <color rgba="0.870588235294 0.811764705882 0.764705882353 1.0"/>
  </material>
  <!-- World -->
  <link name="world">
   </link>
  <!-- World fixed joint -->
  <joint name="world_fixed" type="fixed">
    <parent link="world"/>
    <child link="base_link"/>
  </joint>
  <!-- Base Link -->
  <link name="base_link">
    <inertial>
      <mass value="0.2331188062"/>
      <origin xyz="-2.548e-05 -0.00495518 0.02321769"/>
      <inertia ixx="0.0001796" ixy="6e-08" ixz="5e-08" iyy="0.00017198" iyz="1.93e-06" izz="0.00027331"/>
    </inertial>
    <visual>
      <geometry>
        <mesh filename="package://open_manipulator_description/meshes/base_link.dae"/>
      </geometry>
      <material name="grey"/>
    </visual>
    <collision>
      <geometry>
        <mesh filename="package://open_manipulator_description/meshes/base_link.dae"/>
      </geometry>
    </collision>
  </link>
  <!-- Link 1 -->
  <link name="link1">
    <visual>
      <geometry>
        <mesh filename="package://open_manipulator_description/meshes/link1.dae"/>
      </geometry>
      <material name="grey"/>
    </visual>
    <collision>
      <geometry>
        <mesh filename="package://open_manipulator_description/meshes/link1.dae"/>
      </geometry>
    </collision>
    <inertial>
      <mass value="0.2148954"/>
      <origin xyz="0.00209897 -3.145e-05 0.03141"/>
      <inertia ixx="0.0001072" ixy="0" ixz="2.16e-06" iyy="0.00012565" iyz="-3e-08" izz="6.775e-05"/>
    </inertial>
  </link>
  <!-- Joint 1 -->
  <joint name="id_1" type="revolute">
    <parent link="base_link"/>
    <child link="link1"/>
    <origin xyz="0 0 0.0405"/>
    <axis xyz="0 0 1"/>
    <limit effort="3.1" lower="-3.14159265359" upper="3.14159265359" velocity="2.8"/>
  </joint>
  <!-- Transmission 1 -->
  <transmission name="tran1">
    <type>transmission_interface/SimpleTransmission</type>
    <joint name="id_1">
      <hardwareInterface>hardware_interface/EffortJointInterface</hardwareInterface>
    </joint>
    <actuator name="motor1">
      <hardwareInterface>hardware_interface/EffortJointInterface</hardwareInterface>
      <mechanicalReduction>1</mechanicalReduction>
    </actuator>
  </transmission>
  <!--  Link 2-->
  <link name="link2">
    <visual>
      <geometry>
        <mesh filename="package://open_manipulator_description/meshes/link2.dae"/>
      </geometry>
      <material name="grey"/>
    </visual>
    <collision>
      <geometry>
        <mesh filename="package://open_manipulator_description/meshes/link2.dae"/>
      </geometry>
    </collision>
    <inertial>
      <mass value="0.3501961"/>
      <origin xyz="0.00134144 -3.013e-05 0.13471054"/>
      <inertia ixx="0.00136041" ixy="1.4e-07" ixz="1.848e-08" iyy="0.00140065" iyz="-9.8e-07" izz="0.00012542"/>
    </inertial>
  </link>
  <!--  Joint 2 -->
  <joint name="id_2" type="revolute">
    <parent link="link1"/>
    <child link="link2"/>
    <origin xyz="0 0 0.056"/>
    <axis xyz="1 0 0"/>
    <limit effort="9.9" lower="-1.92" upper="1.83" velocity="2.9"/>
  </joint>
  <!-- Transmission 2 -->
  <transmission name="tran2">
    <type>transmission_interface/SimpleTransmission</type>
    <joint name="id_2">
      <hardwareInterface>hardware_interface/EffortJointInterface</hardwareInterface>
    </joint>
    <actuator name="motor2">
      <hardwareInterface>hardware_interface/EffortJointInterface</hardwareInterface>
      <mechanicalReduction>1</mechanicalReduction>
    </actuator>
  </transmission>
  <!--  Link 3 -->
  <link name="link3">
    <visual>
      <geometry>
        <mesh filename="package://open_manipulator_description/meshes/link3.dae"/>
      </geometry>
      <material name="grey"/>
    </visual>
    <collision>
      <geometry>
        <mesh filename="package://open_manipulator_description/meshes/link3.dae"/>
      </geometry>
    </collision>
    <inertial>
      <mass value="0.20522109"/>
      <origin xyz="-1.698e-05 0.00399677 0.12984563"/>
      <inertia ixx="0.00084745" ixy="4e-08" ixz="-1.7e-07" iyy="0.00083862" iyz="-9.387e-05" izz="9.478e-05"/>
    </inertial>
  </link>
  <!--  Joint 3 -->
  <joint name="id_3" type="revolute">
    <parent link="link2"/>
    <child link="link3"/>
    <origin xyz="0 0 .1935"/>
    <axis xyz="1 0 0"/>
    <limit effort="9.9" lower="-2.33" upper="2.36" velocity="2.9"/>
  </joint>
  <!-- Transmission 3 -->
  <transmission name="tran3">
    <type>transmission_interface/SimpleTransmission</type>
    <joint name="id_3">
      <hardwareInterface>hardware_interface/EffortJointInterface</hardwareInterface>
    </joint>
    <actuator name="motor3">
      <hardwareInterface>hardware_interface/EffortJointInterface</hardwareInterface>
      <mechanicalReduction>1</mechanicalReduction>
    </actuator>
  </transmission>
  <!--  Link 4 -->
  <link name="link4">
    <visual>
      <geometry>
        <mesh filename="package://open_manipulator_description/meshes/link4.dae"/>
      </geometry>
      <material name="grey"/>
    </visual>
    <collision>
      <geometry>
        <mesh filename="package://open_manipulator_description/meshes/link4.dae"/>
      </geometry>
    </collision>
    <inertial>
      <mass value="0.11378884"/>
      <origin xyz="-0.00164387 3.504e-05 0.02301193"/>
      <inertia ixx="4.08e-05" ixy="1e-08" ixz="4.4e-07" iyy="4.422e-05" iyz="1.3e-07" izz="2.465e-05"/>
    </inertial>
  </link>
  <!--  Joint 4-->
  <joint name="id_4" type="revolute">
    <parent link="link3"/>
    <child link="link4"/>
    <origin xyz="0 0 0.201"/>
    <axis xyz="0 0 1"/>
    <limit effort="3.1" lower="-3.14159265359" upper="3.14159265359" velocity="2.8"/>
  </joint>
  <!-- Transmission 4 -->
  <transmission name="tran4">
    <type>transmission_interface/SimpleTransmission</type>
    <joint name="id_4">
      <hardwareInterface>hardware_interface/EffortJointInterface</hardwareInterface>
    </joint>
    <actuator name="motor4">
      <hardwareInterface>hardware_interface/EffortJointInterface</hardwareInterface>
      <mechanicalReduction>1</mechanicalReduction>
    </actuator>
  </transmission>
  <!--  Link 5 -->
  <link name="link5">
    <visual>
      <geometry>
        <mesh filename="package://open_manipulator_description/meshes/link5.dae"/>
      </geometry>
      <material name="grey"/>
    </visual>
    <collision>
      <geometry>
        <mesh filename="package://open_manipulator_description/meshes/link5.dae"/>
      </geometry>
    </collision>
    <inertial>
      <mass value="0.12222061"/>
      <origin xyz="-2.083e-05 -0.01576432 0.03777592"/>
      <inertia ixx="6.096e-05" ixy="1e-08" ixz="-1e-08" iyy="4.934e-05" iyz="-8.17e-06" izz="4.684e-05"/>
    </inertial>
  </link>
  <!--  Joint 5-->
  <joint name="id_5" type="revolute">
    <parent link="link4"/>
    <child link="link5"/>
    <origin xyz="0 0 0.0405"/>
    <axis xyz="1 0 0"/>
    <limit effort="3.1" lower="-2.0" upper="1.69" velocity="2.8"/>
  </joint>
  <!-- Transmission 5 -->
  <transmission name="tran5">
    <type>transmission_interface/SimpleTransmission</type>
    <joint name="id_5">
      <hardwareInterface>hardware_interface/EffortJointInterface</hardwareInterface>
    </joint>
    <actuator name="motor5">
      <hardwareInterface>hardware_interface/EffortJointInterface</hardwareInterface>
      <mechanicalReduction>1</mechanicalReduction>
    </actuator>
  </transmission>
  <!--  Link 6 -->
  <link name="link6">
    <inertial>
      <mass value="0.12977859"/>
      <origin xyz="-2.637e-05 -0.01554872 0.02453859"/>
      <inertia ixx="6.317e-05" ixy="1e-08" ixz="2e-08" iyy="6.152e-05" iyz="9.09e-06" izz="5.762e-05"/>
    </inertial>
    <visual>
      <geometry>
        <mesh filename="package://open_manipulator_description/meshes/link6.dae"/>
      </geometry>
      <material name="grey"/>
    </visual>
    <collision>
      <geometry>
        <mesh filename="package://open_manipulator_description/meshes/link6.dae"/>
      </geometry>
    </collision>
  </link>
  <!--  Joint 6 -->
  <joint name="id_6" type="revolute">
    <origin xyz="0 0 0.064"/>
    <parent link="link5"/>
    <child link="link6"/>
    <axis xyz="0 0 1"/>
    <limit effort="3.1" lower="-3.14159265359" upper="3.14159265359" velocity="2.8"/>
  </joint>
  <!-- Transmission 6 -->
  <transmission name="tran6">
    <type>transmission_interface/SimpleTransmission</type>
    <joint name="id_6">
      <hardwareInterface>hardware_interface/EffortJointInterface</hardwareInterface>
    </joint>
    <actuator name="motor6">
      <hardwareInterface>hardware_interface/EffortJointInterface</hardwareInterface>
      <mechanicalReduction>1</mechanicalReduction>
    </actuator>
  </transmission>
  <!-- Link 7-->
  <link name="link7">
    <inertial>
      <mass value="0.00482"/>
      <origin xyz="-2.637e-05 -0.01554872 0.02453859"/>
      <inertia ixx="3.65e-07" ixy="1.58e-07" ixz="7.033e-08" iyy="4.71e-07" iyz="5e-08" izz="7.51e-07"/>
    </inertial>
    <visual>
      <geometry>
        <mesh filename="package://open_manipulator_description/meshes/link7.dae"/>
      </geometry>
      <material name="grey"/>
    </visual>
    <collision>
      <geometry>
        <mesh filename="package://open_manipulator_description/meshes/link7.dae"/>
      </geometry>
    </collision>
  </link>
  <!-- Joint 7 -->
  <joint name="id_7" type="revolute">
    <origin xyz="0 0 0.039"/>
    <parent link="link6"/>
    <child link="link7"/>
    <axis xyz="0 0 1"/>
    <limit effort="3.1" lower="-3.14159265359" upper="3.14159265359" velocity="2.8"/>
  </joint>
  <!-- Transmission 7 -->
  <transmission name="tran7">
    <type>transmission_interface/SimpleTransmission</type>
    <joint name="id_7">
      <hardwareInterface>hardware_interface/EffortJointInterface</hardwareInterface>
    </joint>
    <actuator name="motor7">
      <hardwareInterface>hardware_interface/EffortJointInterface</hardwareInterface>
      <mechanicalReduction>1</mechanicalReduction>
    </actuator>
  </transmission>
  <!--  Gripper Left-->
  <link name="gripper_l">
    <inertial>
      <mass value="0.01838602"/>
      <origin xyz="0.00300341 0 0.0187682"/>
      <inertia ixx="4.9e-06" ixy="0" ixz="3.2e-07" iyy="4.35e-06" iyz="0" izz="1.54e-06"/>
    </inertial>
    <visual>
      <geometry>
        <mesh filename="package://open_manipulator_description/meshes/gripper.dae"/>
      </geometry>
      <material name="grey"/>
    </visual>
    <collision>
      <geometry>
        <mesh filename="package://open_manipulator_description/meshes/gripper.dae"/>
      </geometry>
    </collision>
  </link>
  <!--Gripper Left Joint -->
  <joint name="joint8" type="prismatic">
    <origin rpy="0 0 3.14159265359" xyz="-0.015 0 0.0595"/>
    <parent link="link6"/>
    <child link="gripper_l"/>
    <axis xyz="1 0 0"/>
    <limit effort=".1" lower="-.033" upper="0" velocity="0.1"/>
    <mimic joint="id_7" multiplier="-0.01" offset="-0.0110133334"/>
  </joint>
  <!--  Gripper Right -->
  <link name="gripper_r">
    <inertial>
      <mass value="0.01838602"/>
      <origin xyz="-0.00300341 0 0.0187682"/>
      <inertia ixx="4.9e-06" ixy="0" ixz="3.2e-07" iyy="4.35e-06" iyz="0" izz="1.54e-06"/>
    </inertial>
    <visual>
      <geometry>
        <mesh filename="package://open_manipulator_description/meshes/gripper.dae"/>
      </geometry>
      <material name="grey"/>
    </visual>
    <collision>
      <geometry>
        <mesh filename="package://open_manipulator_description/meshes/gripper.dae"/>
      </geometry>
    </collision>
  </link>
  <!--Gripper Right Joint -->
  <joint name="joint9" type="prismatic">
    <origin xyz="0.015 0 0.0595"/>
    <parent link="link6"/>
    <child link="gripper_r"/>
    <axis xyz="1 0 0"/>
    <limit effort=".1" lower="0" upper=".033" velocity="0.1"/>
    <mimic joint="joint8" multiplier="1" offset="0"/>
  </joint>
</robot>
